Workbook
Name scopus__6: 'BASE DE DATOS SCOPUS'!$B$4:$M$19

Sheet BASE DE DATOS SCOPUS
B2: Autores | C2: Título | D2: Año | E2: Revista | F2: Resumen en 2 palabras | G2: Palabras clave | H2: Editorial/Publicación | I2: Idioma | J2: Tipo de documento | K2: DOI (acostumbra a mantenerse igual) | L2: Ciudad de publicación | M2: País de estudio | Q2: TIPO SCOPUS/WOS
B3: Authors | C3: Title | D3: Year | E3: Source title | F3: Abstract | G3: Author Keywords | H3: Publisher | I3: Language of Original Document | J3: Document Type | K3: DOI | L3: Correspondence Address | M3: Country of study | Q3: TIPO SCOPUS/WOS
B4: Authors | C4: Title | D4: Year | E4: Journal | F4: Abstract | G4: Keywords | H4: Publisher/Editorial | I4: Language | J4: Document Type | K4: DOI | L4: City of publication | M4: Country of study | Q4: TIPO SCOPUS/WOS
A5: 2 | B5: =+HLOOKUP(B$3,'PEGAR DATOS'!A:AT,$A5,0) -> #N/A | C5: =+HLOOKUP(C$3,'PEGAR DATOS'!B:AU,$A5,0) -> #N/A | D5: =+HLOOKUP(D$3,'PEGAR DATOS'!C:AV,$A5,0) -> #N/A | E5: =+HLOOKUP(E$3,'PEGAR DATOS'!D:AW,$A5,0) -> #N/A | F5: =+HLOOKUP(F$3,'PEGAR DATOS'!E:AX,$A5,0) -> #N/A | G5: =+HLOOKUP(G$3,'PEGAR DATOS'!F:AY,$A5,0) -> #N/A | H5: =+HLOOKUP(H$3,'PEGAR DATOS'!G:AZ,$A5,0) -> #N/A | I5: =+HLOOKUP(I$3,'PEGAR DATOS'!H:BA,$A5,0) -> #N/A | J5: =+HLOOKUP(J$3,'PEGAR DATOS'!I:BB,$A5,0) -> #N/A | K5: =+HLOOKUP(K$3,'PEGAR DATOS'!J:BC,$A5,0) -> #N/A | L5: =+HLOOKUP(L$3,'PEGAR DATOS'!$1:$450,$A5,0) -> #N/A
A6: 3 | B6: =+HLOOKUP(B$3,'PEGAR DATOS'!A:AT,$A6,0) -> #N/A | C6: =+HLOOKUP(C$3,'PEGAR DATOS'!B:AU,$A6,0) -> #N/A | D6: =+HLOOKUP(D$3,'PEGAR DATOS'!C:AV,$A6,0) -> #N/A | E6: =+HLOOKUP(E$3,'PEGAR DATOS'!D:AW,$A6,0) -> #N/A | F6: =+HLOOKUP(F$3,'PEGAR DATOS'!E:AX,$A6,0) -> #N/A | G6: =+HLOOKUP(G$3,'PEGAR DATOS'!F:AY,$A6,0) -> #N/A | H6: =+HLOOKUP(H$3,'PEGAR DATOS'!G:AZ,$A6,0) -> #N/A | I6: =+HLOOKUP(I$3,'PEGAR DATOS'!H:BA,$A6,0) -> #N/A | J6: =+HLOOKUP(J$3,'PEGAR DATOS'!I:BB,$A6,0) -> #N/A | K6: =+HLOOKUP(K$3,'PEGAR DATOS'!J:BC,$A6,0) -> #N/A | L6: =+HLOOKUP(L$3,'PEGAR DATOS'!$1:$450,$A6,0) -> #N/A
A7: 4 | B7: =+HLOOKUP(B$3,'PEGAR DATOS'!A:AT,$A7,0) -> #N/A | C7: =+HLOOKUP(C$3,'PEGAR DATOS'!B:AU,$A7,0) -> #N/A | D7: =+HLOOKUP(D$3,'PEGAR DATOS'!C:AV,$A7,0) -> #N/A | E7: =+HLOOKUP(E$3,'PEGAR DATOS'!D:AW,$A7,0) -> #N/A | F7: =+HLOOKUP(F$3,'PEGAR DATOS'!E:AX,$A7,0) -> #N/A | G7: =+HLOOKUP(G$3,'PEGAR DATOS'!F:AY,$A7,0) -> #N/A | H7: =+HLOOKUP(H$3,'PEGAR DATOS'!G:AZ,$A7,0) -> #N/A | I7: =+HLOOKUP(I$3,'PEGAR DATOS'!H:BA,$A7,0) -> #N/A | J7: =+HLOOKUP(J$3,'PEGAR DATOS'!I:BB,$A7,0) -> #N/A | K7: =+HLOOKUP(K$3,'PEGAR DATOS'!J:BC,$A7,0) -> #N/A | L7: =+HLOOKUP(L$3,'PEGAR DATOS'!$1:$450,$A7,0) -> #N/A
A8: 5 | B8: =+HLOOKUP(B$3,'PEGAR DATOS'!A:AT,$A8,0) -> #N/A | C8: =+HLOOKUP(C$3,'PEGAR DATOS'!B:AU,$A8,0) -> #N/A | D8: =+HLOOKUP(D$3,'PEGAR DATOS'!C:AV,$A8,0) -> #N/A | E8: =+HLOOKUP(E$3,'PEGAR DATOS'!D:AW,$A8,0) -> #N/A | F8: =+HLOOKUP(F$3,'PEGAR DATOS'!E:AX,$A8,0) -> #N/A | G8: =+HLOOKUP(G$3,'PEGAR DATOS'!F:AY,$A8,0) -> #N/A | H8: =+HLOOKUP(H$3,'PEGAR DATOS'!G:AZ,$A8,0) -> #N/A | I8: =+HLOOKUP(I$3,'PEGAR DATOS'!H:BA,$A8,0) -> #N/A | J8: =+HLOOKUP(J$3,'PEGAR DATOS'!I:BB,$A8,0) -> #N/A | K8: =+HLOOKUP(K$3,'PEGAR DATOS'!J:BC,$A8,0) -> #N/A | L8: =+HLOOKUP(L$3,'PEGAR DATOS'!$1:$450,$A8,0) -> #N/A
A9: 6 | B9: =+HLOOKUP(B$3,'PEGAR DATOS'!A:AT,$A9,0) -> #N/A | C9: =+HLOOKUP(C$3,'PEGAR DATOS'!B:AU,$A9,0) -> #N/A | D9: =+HLOOKUP(D$3,'PEGAR DATOS'!C:AV,$A9,0) -> #N/A | E9: =+HLOOKUP(E$3,'PEGAR DATOS'!D:AW,$A9,0) -> #N/A | F9: =+HLOOKUP(F$3,'PEGAR DATOS'!E:AX,$A9,0) -> #N/A | G9: =+HLOOKUP(G$3,'PEGAR DATOS'!F:AY,$A9,0) -> #N/A | H9: =+HLOOKUP(H$3,'PEGAR DATOS'!G:AZ,$A9,0) -> #N/A | I9: =+HLOOKUP(I$3,'PEGAR DATOS'!H:BA,$A9,0) -> #N/A | J9: =+HLOOKUP(J$3,'PEGAR DATOS'!I:BB,$A9,0) -> #N/A | K9: =+HLOOKUP(K$3,'PEGAR DATOS'!J:BC,$A9,0) -> #N/A | L9: =+HLOOKUP(L$3,'PEGAR DATOS'!$1:$450,$A9,0) -> #N/A
A10: 7 | B10: =+HLOOKUP(B$3,'PEGAR DATOS'!A:AT,$A10,0) -> #N/A | C10: =+HLOOKUP(C$3,'PEGAR DATOS'!B:AU,$A10,0) -> #N/A | D10: =+HLOOKUP(D$3,'PEGAR DATOS'!C:AV,$A10,0) -> #N/A | E10: =+HLOOKUP(E$3,'PEGAR DATOS'!D:AW,$A10,0) -> #N/A | F10: =+HLOOKUP(F$3,'PEGAR DATOS'!E:AX,$A10,0) -> #N/A | G10: =+HLOOKUP(G$3,'PEGAR DATOS'!F:AY,$A10,0) -> #N/A | H10: =+HLOOKUP(H$3,'PEGAR DATOS'!G:AZ,$A10,0) -> #N/A | I10: =+HLOOKUP(I$3,'PEGAR DATOS'!H:BA,$A10,0) -> #N/A | J10: =+HLOOKUP(J$3,'PEGAR DATOS'!I:BB,$A10,0) -> #N/A | K10: =+HLOOKUP(K$3,'PEGAR DATOS'!J:BC,$A10,0) -> #N/A | L10: =+HLOOKUP(L$3,'PEGAR DATOS'!$1:$450,$A10,0) -> #N/A
A11: 8 | B11: =+HLOOKUP(B$3,'PEGAR DATOS'!A:AT,$A11,0) -> #N/A | C11: =+HLOOKUP(C$3,'PEGAR DATOS'!B:AU,$A11,0) -> #N/A | D11: =+HLOOKUP(D$3,'PEGAR DATOS'!C:AV,$A11,0) -> #N/A | E11: =+HLOOKUP(E$3,'PEGAR DATOS'!D:AW,$A11,0) -> #N/A | F11: =+HLOOKUP(F$3,'PEGAR DATOS'!E:AX,$A11,0) -> #N/A | G11: =+HLOOKUP(G$3,'PEGAR DATOS'!F:AY,$A11,0) -> #N/A | H11: =+HLOOKUP(H$3,'PEGAR DATOS'!G:AZ,$A11,0) -> #N/A | I11: =+HLOOKUP(I$3,'PEGAR DATOS'!H:BA,$A11,0) -> #N/A | J11: =+HLOOKUP(J$3,'PEGAR DATOS'!I:BB,$A11,0) -> #N/A | K11: =+HLOOKUP(K$3,'PEGAR DATOS'!J:BC,$A11,0) -> #N/A | L11: =+HLOOKUP(L$3,'PEGAR DATOS'!$1:$450,$A11,0) -> #N/A
A12: 9 | B12: =+HLOOKUP(B$3,'PEGAR DATOS'!A:AT,$A12,0) -> #N/A | C12: =+HLOOKUP(C$3,'PEGAR DATOS'!B:AU,$A12,0) -> #N/A | D12: =+HLOOKUP(D$3,'PEGAR DATOS'!C:AV,$A12,0) -> #N/A | E12: =+HLOOKUP(E$3,'PEGAR DATOS'!D:AW,$A12,0) -> #N/A | F12: =+HLOOKUP(F$3,'PEGAR DATOS'!E:AX,$A12,0) -> #N/A | G12: =+HLOOKUP(G$3,'PEGAR DATOS'!F:AY,$A12,0) -> #N/A | H12: =+HLOOKUP(H$3,'PEGAR DATOS'!G:AZ,$A12,0) -> #N/A | I12: =+HLOOKUP(I$3,'PEGAR DATOS'!H:BA,$A12,0) -> #N/A | J12: =+HLOOKUP(J$3,'PEGAR DATOS'!I:BB,$A12,0) -> #N/A | K12: =+HLOOKUP(K$3,'PEGAR DATOS'!J:BC,$A12,0) -> #N/A | L12: =+HLOOKUP(L$3,'PEGAR DATOS'!$1:$450,$A12,0) -> #N/A
A13: 10 | B13: =+HLOOKUP(B$3,'PEGAR DATOS'!A:AT,$A13,0) -> #N/A | C13: =+HLOOKUP(C$3,'PEGAR DATOS'!B:AU,$A13,0) -> #N/A | D13: =+HLOOKUP(D$3,'PEGAR DATOS'!C:AV,$A13,0) -> #N/A | E13: =+HLOOKUP(E$3,'PEGAR DATOS'!D:AW,$A13,0) -> #N/A | F13: =+HLOOKUP(F$3,'PEGAR DATOS'!E:AX,$A13,0) -> #N/A | G13: =+HLOOKUP(G$3,'PEGAR DATOS'!F:AY,$A13,0) -> #N/A | H13: =+HLOOKUP(H$3,'PEGAR DATOS'!G:AZ,$A13,0) -> #N/A | I13: =+HLOOKUP(I$3,'PEGAR DATOS'!H:BA,$A13,0) -> #N/A | J13: =+HLOOKUP(J$3,'PEGAR DATOS'!I:BB,$A13,0) -> #N/A | K13: =+HLOOKUP(K$3,'PEGAR DATOS'!J:BC,$A13,0) -> #N/A | L13: =+HLOOKUP(L$3,'PEGAR DATOS'!$1:$450,$A13,0) -> #N/A
A14: 11 | B14: =+HLOOKUP(B$3,'PEGAR DATOS'!A:AT,$A14,0) -> #N/A | C14: =+HLOOKUP(C$3,'PEGAR DATOS'!B:AU,$A14,0) -> #N/A | D14: =+HLOOKUP(D$3,'PEGAR DATOS'!C:AV,$A14,0) -> #N/A | E14: =+HLOOKUP(E$3,'PEGAR DATOS'!D:AW,$A14,0) -> #N/A | F14: =+HLOOKUP(F$3,'PEGAR DATOS'!E:AX,$A14,0) -> #N/A | G14: =+HLOOKUP(G$3,'PEGAR DATOS'!F:AY,$A14,0) -> #N/A | H14: =+HLOOKUP(H$3,'PEGAR DATOS'!G:AZ,$A14,0) -> #N/A | I14: =+HLOOKUP(I$3,'PEGAR DATOS'!H:BA,$A14,0) -> #N/A | J14: =+HLOOKUP(J$3,'PEGAR DATOS'!I:BB,$A14,0) -> #N/A | K14: =+HLOOKUP(K$3,'PEGAR DATOS'!J:BC,$A14,0) -> #N/A | L14: =+HLOOKUP(L$3,'PEGAR DATOS'!$1:$450,$A14,0) -> #N/A
A15: 12 | B15: =+HLOOKUP(B$3,'PEGAR DATOS'!A:AT,$A15,0) -> #N/A | C15: =+HLOOKUP(C$3,'PEGAR DATOS'!B:AU,$A15,0) -> #N/A | D15: =+HLOOKUP(D$3,'PEGAR DATOS'!C:AV,$A15,0) -> #N/A | E15: =+HLOOKUP(E$3,'PEGAR DATOS'!D:AW,$A15,0) -> #N/A | F15: =+HLOOKUP(F$3,'PEGAR DATOS'!E:AX,$A15,0) -> #N/A | G15: =+HLOOKUP(G$3,'PEGAR DATOS'!F:AY,$A15,0) -> #N/A | H15: =+HLOOKUP(H$3,'PEGAR DATOS'!G:AZ,$A15,0) -> #N/A | I15: =+HLOOKUP(I$3,'PEGAR DATOS'!H:BA,$A15,0) -> #N/A | J15: =+HLOOKUP(J$3,'PEGAR DATOS'!I:BB,$A15,0) -> #N/A | K15: =+HLOOKUP(K$3,'PEGAR DATOS'!J:BC,$A15,0) -> #N/A | L15: =+HLOOKUP(L$3,'PEGAR DATOS'!$1:$450,$A15,0) -> #N/A
A16: 13 | B16: =+HLOOKUP(B$3,'PEGAR DATOS'!A:AT,$A16,0) -> #N/A | C16: =+HLOOKUP(C$3,'PEGAR DATOS'!B:AU,$A16,0) -> #N/A | D16: =+HLOOKUP(D$3,'PEGAR DATOS'!C:AV,$A16,0) -> #N/A | E16: =+HLOOKUP(E$3,'PEGAR DATOS'!D:AW,$A16,0) -> #N/A | F16: =+HLOOKUP(F$3,'PEGAR DATOS'!E:AX,$A16,0) -> #N/A | G16: =+HLOOKUP(G$3,'PEGAR DATOS'!F:AY,$A16,0) -> #N/A | H16: =+HLOOKUP(H$3,'PEGAR DATOS'!G:AZ,$A16,0) -> #N/A | I16: =+HLOOKUP(I$3,'PEGAR DATOS'!H:BA,$A16,0) -> #N/A | J16: =+HLOOKUP(J$3,'PEGAR DATOS'!I:BB,$A16,0) -> #N/A | K16: =+HLOOKUP(K$3,'PEGAR DATOS'!J:BC,$A16,0) -> #N/A | L16: =+HLOOKUP(L$3,'PEGAR DATOS'!$1:$450,$A16,0) -> #N/A
... A405: 402 | B405: =+HLOOKUP(B$3,'PEGAR DATOS'!A:AT,$A405,0) -> #N/A | C405: =+HLOOKUP(C$3,'PEGAR DATOS'!B:AU,$A405,0) -> #N/A | D405: =+HLOOKUP(D$3,'PEGAR DATOS'!C:AV,$A405,0) -> #N/A | E405: =+HLOOKUP(E$3,'PEGAR DATOS'!D:AW,$A405,0) -> #N/A | F405: =+HLOOKUP(F$3,'PEGAR DATOS'!E:AX,$A405,0) -> #N/A | G405: =+HLOOKUP(G$3,'PEGAR DATOS'!F:AY,$A405,0) -> #N/A | H405: =+HLOOKUP(H$3,'PEGAR DATOS'!G:AZ,$A405,0) -> #N/A | I405: =+HLOOKUP(I$3,'PEGAR DATOS'!H:BA,$A405,0) -> #N/A | J405: =+HLOOKUP(J$3,'PEGAR DATOS'!I:BB,$A405,0) -> #N/A | K405: =+HLOOKUP(K$3,'PEGAR DATOS'!J:BC,$A405,0) -> #N/A | L405: =+HLOOKUP(L$3,'PEGAR DATOS'!$1:$450,$A405,0) -> #N/A
A406: 403 | B406: =+HLOOKUP(B$3,'PEGAR DATOS'!A:AT,$A406,0) -> #N/A | C406: =+HLOOKUP(C$3,'PEGAR DATOS'!B:AU,$A406,0) -> #N/A | D406: =+HLOOKUP(D$3,'PEGAR DATOS'!C:AV,$A406,0) -> #N/A | E406: =+HLOOKUP(E$3,'PEGAR DATOS'!D:AW,$A406,0) -> #N/A | F406: =+HLOOKUP(F$3,'PEGAR DATOS'!E:AX,$A406,0) -> #N/A | G406: =+HLOOKUP(G$3,'PEGAR DATOS'!F:AY,$A406,0) -> #N/A | H406: =+HLOOKUP(H$3,'PEGAR DATOS'!G:AZ,$A406,0) -> #N/A | I406: =+HLOOKUP(I$3,'PEGAR DATOS'!H:BA,$A406,0) -> #N/A | J406: =+HLOOKUP(J$3,'PEGAR DATOS'!I:BB,$A406,0) -> #N/A | K406: =+HLOOKUP(K$3,'PEGAR DATOS'!J:BC,$A406,0) -> #N/A | L406: =+HLOOKUP(L$3,'PEGAR DATOS'!$1:$450,$A406,0) -> #N/A | Q406: Scopus
A407: 404 | B407: =+HLOOKUP(B$3,'PEGAR DATOS'!A:AT,$A407,0) -> #N/A | C407: =+HLOOKUP(C$3,'PEGAR DATOS'!B:AU,$A407,0) -> #N/A | D407: =+HLOOKUP(D$3,'PEGAR DATOS'!C:AV,$A407,0) -> #N/A | E407: =+HLOOKUP(E$3,'PEGAR DATOS'!D:AW,$A407,0) -> #N/A | F407: =+HLOOKUP(F$3,'PEGAR DATOS'!E:AX,$A407,0) -> #N/A | G407: =+HLOOKUP(G$3,'PEGAR DATOS'!F:AY,$A407,0) -> #N/A | H407: =+HLOOKUP(H$3,'PEGAR DATOS'!G:AZ,$A407,0) -> #N/A | I407: =+HLOOKUP(I$3,'PEGAR DATOS'!H:BA,$A407,0) -> #N/A | J407: =+HLOOKUP(J$3,'PEGAR DATOS'!I:BB,$A407,0) -> #N/A | K407: =+HLOOKUP(K$3,'PEGAR DATOS'!J:BC,$A407,0) -> #N/A | L407: =+HLOOKUP(L$3,'PEGAR DATOS'!$1:$450,$A407,0) -> #N/A | Q407: Scopus
A408: 405 | B408: =+HLOOKUP(B$3,'PEGAR DATOS'!A:AT,$A408,0) -> #N/A | C408: =+HLOOKUP(C$3,'PEGAR DATOS'!B:AU,$A408,0) -> #N/A | D408: =+HLOOKUP(D$3,'PEGAR DATOS'!C:AV,$A408,0) -> #N/A | E408: =+HLOOKUP(E$3,'PEGAR DATOS'!D:AW,$A408,0) -> #N/A | F408: =+HLOOKUP(F$3,'PEGAR DATOS'!E:AX,$A408,0) -> #N/A | G408: =+HLOOKUP(G$3,'PEGAR DATOS'!F:AY,$A408,0) -> #N/A | H408: =+HLOOKUP(H$3,'PEGAR DATOS'!G:AZ,$A408,0) -> #N/A | I408: =+HLOOKUP(I$3,'PEGAR DATOS'!H:BA,$A408,0) -> #N/A | J408: =+HLOOKUP(J$3,'PEGAR DATOS'!I:BB,$A408,0) -> #N/A | K408: =+HLOOKUP(K$3,'PEGAR DATOS'!J:BC,$A408,0) -> #N/A | L408: =+HLOOKUP(L$3,'PEGAR DATOS'!$1:$450,$A408,0) -> #N/A | Q408: Scopus
A409: 406 | B409: =+HLOOKUP(B$3,'PEGAR DATOS'!A:AT,$A409,0) -> #N/A | C409: =+HLOOKUP(C$3,'PEGAR DATOS'!B:AU,$A409,0) -> #N/A | D409: =+HLOOKUP(D$3,'PEGAR DATOS'!C:AV,$A409,0) -> #N/A | E409: =+HLOOKUP(E$3,'PEGAR DATOS'!D:AW,$A409,0) -> #N/A | F409: =+HLOOKUP(F$3,'PEGAR DATOS'!E:AX,$A409,0) -> #N/A | G409: =+HLOOKUP(G$3,'PEGAR DATOS'!F:AY,$A409,0) -> #N/A | H409: =+HLOOKUP(H$3,'PEGAR DATOS'!G:AZ,$A409,0) -> #N/A | I409: =+HLOOKUP(I$3,'PEGAR DATOS'!H:BA,$A409,0) -> #N/A | J409: =+HLOOKUP(J$3,'PEGAR DATOS'!I:BB,$A409,0) -> #N/A | K409: =+HLOOKUP(K$3,'PEGAR DATOS'!J:BC,$A409,0) -> #N/A | L409: =+HLOOKUP(L$3,'PEGAR DATOS'!$1:$450,$A409,0) -> #N/A | Q409: Scopus
A410: 407 | B410: =+HLOOKUP(B$3,'PEGAR DATOS'!A:AT,$A410,0) -> #N/A | C410: =+HLOOKUP(C$3,'PEGAR DATOS'!B:AU,$A410,0) -> #N/A | D410: =+HLOOKUP(D$3,'PEGAR DATOS'!C:AV,$A410,0) -> #N/A | E410: =+HLOOKUP(E$3,'PEGAR DATOS'!D:AW,$A410,0) -> #N/A | F410: =+HLOOKUP(F$3,'PEGAR DATOS'!E:AX,$A410,0) -> #N/A | G410: =+HLOOKUP(G$3,'PEGAR DATOS'!F:AY,$A410,0) -> #N/A | H410: =+HLOOKUP(H$3,'PEGAR DATOS'!G:AZ,$A410,0) -> #N/A | I410: =+HLOOKUP(I$3,'PEGAR DATOS'!H:BA,$A410,0) -> #N/A | J410: =+HLOOKUP(J$3,'PEGAR DATOS'!I:BB,$A410,0) -> #N/A | K410: =+HLOOKUP(K$3,'PEGAR DATOS'!J:BC,$A410,0) -> #N/A | L410: =+HLOOKUP(L$3,'PEGAR DATOS'!$1:$450,$A410,0) -> #N/A | Q410: Scopus
A411: 408 | B411: =+HLOOKUP(B$3,'PEGAR DATOS'!A:AT,$A411,0) -> #N/A | C411: =+HLOOKUP(C$3,'PEGAR DATOS'!B:AU,$A411,0) -> #N/A | D411: =+HLOOKUP(D$3,'PEGAR DATOS'!C:AV,$A411,0) -> #N/A | E411: =+HLOOKUP(E$3,'PEGAR DATOS'!D:AW,$A411,0) -> #N/A | F411: =+HLOOKUP(F$3,'PEGAR DATOS'!E:AX,$A411,0) -> #N/A | G411: =+HLOOKUP(G$3,'PEGAR DATOS'!F:AY,$A411,0) -> #N/A | H411: =+HLOOKUP(H$3,'PEGAR DATOS'!G:AZ,$A411,0) -> #N/A | I411: =+HLOOKUP(I$3,'PEGAR DATOS'!H:BA,$A411,0) -> #N/A | J411: =+HLOOKUP(J$3,'PEGAR DATOS'!I:BB,$A411,0) -> #N/A | K411: =+HLOOKUP(K$3,'PEGAR DATOS'!J:BC,$A411,0) -> #N/A | L411: =+HLOOKUP(L$3,'PEGAR DATOS'!$1:$450,$A411,0) -> #N/A | Q411: Scopus
A412: 409 | B412: =+HLOOKUP(B$3,'PEGAR DATOS'!A:AT,$A412,0) -> #N/A | C412: =+HLOOKUP(C$3,'PEGAR DATOS'!B:AU,$A412,0) -> #N/A | D412: =+HLOOKUP(D$3,'PEGAR DATOS'!C:AV,$A412,0) -> #N/A | E412: =+HLOOKUP(E$3,'PEGAR DATOS'!D:AW,$A412,0) -> #N/A | F412: =+HLOOKUP(F$3,'PEGAR DATOS'!E:AX,$A412,0) -> #N/A | G412: =+HLOOKUP(G$3,'PEGAR DATOS'!F:AY,$A412,0) -> #N/A | H412: =+HLOOKUP(H$3,'PEGAR DATOS'!G:AZ,$A412,0) -> #N/A | I412: =+HLOOKUP(I$3,'PEGAR DATOS'!H:BA,$A412,0) -> #N/A | J412: =+HLOOKUP(J$3,'PEGAR DATOS'!I:BB,$A412,0) -> #N/A | K412: =+HLOOKUP(K$3,'PEGAR DATOS'!J:BC,$A412,0) -> #N/A | L412: =+HLOOKUP(L$3,'PEGAR DATOS'!$1:$450,$A412,0) -> #N/A | Q412: Scopus
A413: 410 | B413: =+HLOOKUP(B$3,'PEGAR DATOS'!A:AT,$A413,0) -> #N/A | C413: =+HLOOKUP(C$3,'PEGAR DATOS'!B:AU,$A413,0) -> #N/A | D413: =+HLOOKUP(D$3,'PEGAR DATOS'!C:AV,$A413,0) -> #N/A | E413: =+HLOOKUP(E$3,'PEGAR DATOS'!D:AW,$A413,0) -> #N/A | F413: =+HLOOKUP(F$3,'PEGAR DATOS'!E:AX,$A413,0) -> #N/A | G413: =+HLOOKUP(G$3,'PEGAR DATOS'!F:AY,$A413,0) -> #N/A | H413: =+HLOOKUP(H$3,'PEGAR DATOS'!G:AZ,$A413,0) -> #N/A | I413: =+HLOOKUP(I$3,'PEGAR DATOS'!H:BA,$A413,0) -> #N/A | J413: =+HLOOKUP(J$3,'PEGAR DATOS'!I:BB,$A413,0) -> #N/A | K413: =+HLOOKUP(K$3,'PEGAR DATOS'!J:BC,$A413,0) -> #N/A | L413: =+HLOOKUP(L$3,'PEGAR DATOS'!$1:$450,$A413,0) -> #N/A | Q413: Scopus
A414: 411 | B414: =+HLOOKUP(B$3,'PEGAR DATOS'!A:AT,$A414,0) -> #N/A | C414: =+HLOOKUP(C$3,'PEGAR DATOS'!B:AU,$A414,0) -> #N/A | D414: =+HLOOKUP(D$3,'PEGAR DATOS'!C:AV,$A414,0) -> #N/A | E414: =+HLOOKUP(E$3,'PEGAR DATOS'!D:AW,$A414,0) -> #N/A | F414: =+HLOOKUP(F$3,'PEGAR DATOS'!E:AX,$A414,0) -> #N/A | G414: =+HLOOKUP(G$3,'PEGAR DATOS'!F:AY,$A414,0) -> #N/A | H414: =+HLOOKUP(H$3,'PEGAR DATOS'!G:AZ,$A414,0) -> #N/A | I414: =+HLOOKUP(I$3,'PEGAR DATOS'!H:BA,$A414,0) -> #N/A | J414: =+HLOOKUP(J$3,'PEGAR DATOS'!I:BB,$A414,0) -> #N/A | K414: =+HLOOKUP(K$3,'PEGAR DATOS'!J:BC,$A414,0) -> #N/A | L414: =+HLOOKUP(L$3,'PEGAR DATOS'!$1:$450,$A414,0) -> #N/A | Q414: Scopus
A415: 412 | B415: =+HLOOKUP(B$3,'PEGAR DATOS'!A:AT,$A415,0) -> #N/A | C415: =+HLOOKUP(C$3,'PEGAR DATOS'!B:AU,$A415,0) -> #N/A | D415: =+HLOOKUP(D$3,'PEGAR DATOS'!C:AV,$A415,0) -> #N/A | E415: =+HLOOKUP(E$3,'PEGAR DATOS'!D:AW,$A415,0) -> #N/A | F415: =+HLOOKUP(F$3,'PEGAR DATOS'!E:AX,$A415,0) -> #N/A | G415: =+HLOOKUP(G$3,'PEGAR DATOS'!F:AY,$A415,0) -> #N/A | H415: =+HLOOKUP(H$3,'PEGAR DATOS'!G:AZ,$A415,0) -> #N/A | I415: =+HLOOKUP(I$3,'PEGAR DATOS'!H:BA,$A415,0) -> #N/A | J415: =+HLOOKUP(J$3,'PEGAR DATOS'!I:BB,$A415,0) -> #N/A | K415: =+HLOOKUP(K$3,'PEGAR DATOS'!J:BC,$A415,0) -> #N/A | L415: =+HLOOKUP(L$3,'PEGAR DATOS'!$1:$450,$A415,0) -> #N/A | Q415: Scopus
A416: 413 | B416: =+HLOOKUP(B$3,'PEGAR DATOS'!A:AT,$A416,0) -> #N/A | C416: =+HLOOKUP(C$3,'PEGAR DATOS'!B:AU,$A416,0) -> #N/A | D416: =+HLOOKUP(D$3,'PEGAR DATOS'!C:AV,$A416,0) -> #N/A | E416: =+HLOOKUP(E$3,'PEGAR DATOS'!D:AW,$A416,0) -> #N/A | F416: =+HLOOKUP(F$3,'PEGAR DATOS'!E:AX,$A416,0) -> #N/A | G416: =+HLOOKUP(G$3,'PEGAR DATOS'!F:AY,$A416,0) -> #N/A | H416: =+HLOOKUP(H$3,'PEGAR DATOS'!G:AZ,$A416,0) -> #N/A | I416: =+HLOOKUP(I$3,'PEGAR DATOS'!H:BA,$A416,0) -> #N/A | J416: =+HLOOKUP(J$3,'PEGAR DATOS'!I:BB,$A416,0) -> #N/A | K416: =+HLOOKUP(K$3,'PEGAR DATOS'!J:BC,$A416,0) -> #N/A | L416: =+HLOOKUP(L$3,'PEGAR DATOS'!$1:$450,$A416,0) -> #N/A | Q416: Scopus
A417: 414 | B417: =+HLOOKUP(B$3,'PEGAR DATOS'!A:AT,$A417,0) -> #N/A | C417: =+HLOOKUP(C$3,'PEGAR DATOS'!B:AU,$A417,0) -> #N/A | D417: =+HLOOKUP(D$3,'PEGAR DATOS'!C:AV,$A417,0) -> #N/A | E417: =+HLOOKUP(E$3,'PEGAR DATOS'!D:AW,$A417,0) -> #N/A | F417: =+HLOOKUP(F$3,'PEGAR DATOS'!E:AX,$A417,0) -> #N/A | G417: =+HLOOKUP(G$3,'PEGAR DATOS'!F:AY,$A417,0) -> #N/A | H417: =+HLOOKUP(H$3,'PEGAR DATOS'!G:AZ,$A417,0) -> #N/A | I417: =+HLOOKUP(I$3,'PEGAR DATOS'!H:BA,$A417,0) -> #N/A | J417: =+HLOOKUP(J$3,'PEGAR DATOS'!I:BB,$A417,0) -> #N/A | K417: =+HLOOKUP(K$3,'PEGAR DATOS'!J:BC,$A417,0) -> #N/A | L417: =+HLOOKUP(L$3,'PEGAR DATOS'!$1:$450,$A417,0) -> #N/A | Q417: Scopus
... A1110: 1107 | B1110: =+HLOOKUP(B$3,'PEGAR DATOS'!A:AT,$A1110,0) -> #N/A | C1110: =+HLOOKUP(C$3,'PEGAR DATOS'!B:AU,$A1110,0) -> #N/A | D1110: =+HLOOKUP(D$3,'PEGAR DATOS'!C:AV,$A1110,0) -> #N/A | E1110: =+HLOOKUP(E$3,'PEGAR DATOS'!D:AW,$A1110,0) -> #N/A | F1110: =+HLOOKUP(F$3,'PEGAR DATOS'!E:AX,$A1110,0) -> #N/A | G1110: =+HLOOKUP(G$3,'PEGAR DATOS'!F:AY,$A1110,0) -> #N/A | H1110: =+HLOOKUP(H$3,'PEGAR DATOS'!G:AZ,$A1110,0) -> #N/A | I1110: =+HLOOKUP(I$3,'PEGAR DATOS'!H:BA,$A1110,0) -> #N/A | J1110: =+HLOOKUP(J$3,'PEGAR DATOS'!I:BB,$A1110,0) -> #N/A | K1110: =+HLOOKUP(K$3,'PEGAR DATOS'!J:BC,$A1110,0) -> #N/A | L1110: =+HLOOKUP(L$3,'PEGAR DATOS'!$1:$450,$A1110,0) -> #N/A | Q1110: Scopus

Sheet DATABASE WOS
A1: Journal | B1: Abstract | C1: Keywords | D1: Publisher/Editorial | E1: Language | F1: Document Type | G1: DOI | H1: City of publication | I1: Country of study | M1: TIPO SCOPUS/WOS

Sheet DATABASE SCIELO
A1: Journal | B1: Abstract | C1: Keywords | D1: Publisher/Editorial | E1: Language | F1: Document Type | G1: DOI | H1: City of publication | I1: Country of study | M1: TIPO SCOPUS/WOS

Sheet DATABASE REDALYC
A1: Journal | B1: Abstract | C1: Keywords | D1: Publisher/Editorial | E1: Language | F1: Document Type | G1: DOI | H1: City of publication | I1: Country of study | M1: TIPO SCOPUS/WOS

Sheet DATABASE PROUEST
A1: Journal | B1: Abstract | C1: Keywords | D1: Publisher/Editorial | E1: Language | F1: Document Type | G1: DOI | H1: City of publication | I1: Country of study | M1: TIPO SCOPUS/WOS

Sheet Figura 1
C1: Identificación y selección de estudios a través de bases de datos
A3: Identification | C3: Registros identificados desde: Base de datos 1 Web of Science (n = 100) Base de datos 2 Scopus (n = 200) | G3: Registros eliminados antes de la selección: Registros duplicados eliminados (n = 30 ) Registros marcados como no elegibles por herramientas de automatización (n = 30) Registros eliminados por otras razones (n = 25 )
A8: Screening | C8: Registros examinados (n = 25 ) | G8: Registros excluidos* (n = 30 )
C12: Informes buscados para recuperar (n = 25 ) | G12: Informes no recuperados (n = 45 )
C16: Informes evaluados para elegibilidad (n = 25 ) | G16: Informes excluidos: Razón 1 (n = 24) Razón 2 (n = 15) Razón 3 (n = 11 ) etc.(colocar la razón específica)
C21: Estudios incluidos en la revisión (n = 40)

Sheet PLANTILLA
A3: Tabla 1 | F3: Tabla 2 | N3: Figura 2 | AA3: Figura 2 | AM3: Figura 3 | AN3: Porcentaje (%) | AS3: Figura 6 | AT3: Absoluto (n) | AU3: Relativa (n/N) | AV3: Porcentaje (%) | BD3: Figura 7 | BE3: Absoluto (n) | BF3: Relativa (n/N) | BG3: Porcentaje (%)
N4: Tendencia de publicaciones por año | AA4: Tendencia de Revistas o editoriales que publicaron | AM4: Mayor frecuencia de países de publicación | AS4: Cantidad y porcentaje por idioma de publicación | BE4: Mayor incidencia de Cantidad de artículos por base de datos
F5: N° | G5: Autor (es) | H5: Título | I5: Año | J5: Revista | K5: País | L5: Base de datos | AS5: Etiquetas de fila | AT5: Absoluto (n) | AU5: Relativa (n/N) | AV5: Porcentaje (%) | BD5: Etiquetas de fila | BE5: Absoluto (n) | BF5: Relativa (n/N) | BG5: Porcentaje (%) | BI5: Etiquetas de fila | BJ5: Absoluto (n)
A6: Base de datos | B6: Frecuencias | F6: 1 | G6: ='BASE DE DATOS SCOPUS'!B5 -> #N/A | H6: ='BASE DE DATOS SCOPUS'!C5 -> #N/A | I6: ='BASE DE DATOS SCOPUS'!D5 -> #N/A | J6: ='BASE DE DATOS SCOPUS'!E5 -> #N/A | K6: ='BASE DE DATOS SCOPUS'!L5 -> #N/A | L6: ='BASE DE DATOS SCOPUS'!Q5 -> 0 | N6: Etiquetas de fila | O6: Absoluto (n) | P6: Relativa (n/N) | Q6: Porcentaje (%) | S6: Etiquetas de fila | T6: Absoluto (n) | AA6: Etiquetas de fila | AB6: Absoluto (n) | AC6: Relativa (n/N) | AD6: Porcentaje (%) | AF6: Etiquetas de fila | AG6: Absoluto (n) | AM6: Etiquetas de fila | AN6: Absoluto (n) | AO6: Relativa (n/N) | AP6: Porcentaje (%) | AS6: English | AT6: 30 | AU6: 1 | AV6: 1 | BD6: Scopus | BE6: 10 | BF6: 0.33333333 | BG6: 0.33333333 | BI6: Scopus | BJ6: 10
B7: Absoluta (n) | C7: Relativa (n/N) | D7: Porcentaje (%) | F7: 2 | G7: Rivera O.; Benites S.; Mendigure J.; Bonilla C.A. | H7: Therapeutic abandonment in multidrug-resistant tuberculosis: Associated factors in a high burden region in Perú; [Abandono terapéutico en tuberculosis multidrogorresistente: factores asociados en una región de alta carga en Perú] | I7: 2019 | J7: Biomedica | K7: ='BASE DE DATOS SCOPUS'!L6 -> #N/A | L7: ='BASE DE DATOS SCOPUS'!Q6 -> 0 | N7: 2021 | O7: 13 | P7: 0.43333333 | Q7: 0.43333333 | S7: 2021 | T7: 13 | AA7: Gaceta Sanitaria | AB7: 1 | AC7: 0.5 | AD7: 0.5 | AF7: Gaceta Sanitaria | AG7: 1 | AM7: Germany | AN7: 2 | AO7: 0.066666667 | AP7: 0.066666667 | AS7: Total general | AT7: 30 | AU7: 1 | AV7: 1 | BD7: Scilo | BE7: 10 | BF7: 0.33333333 | BG7: 0.33333333 | BI7: Scilo | BJ7: 10
A8: Scopus | B8: 613 | C8: =B8/B$10 -> 0.55525362 | D8: =C8*100% -> 0.55525362 | F8: 3 | G8: Andrade G.; Espinoza A. | H8: Significado de psicólogas/os de atención primaria de salud sobre la intervención psicosocial de grupo en el tratamiento de la depresión en Chile | I8: 2019 | J8: Global Health Promotion | K8: ='BASE DE DATOS SCOPUS'!L7 -> #N/A | L8: ='BASE DE DATOS SCOPUS'!Q7 -> 0 | N8: 2022 | O8: 8 | P8: 0.26666667 | Q8: 0.26666667 | S8: 2022 | T8: 8 | AA8: Medwave | AB8: 1 | AC8: 0.5 | AD8: 0.5 | AF8: Medwave | AG8: 1 | AM8: United States | AN8: 10 | AO8: 0.33333333 | AP8: 0.33333333 | BD8: Redallyc | BE8: 10 | BF8: 0.33333333 | BG8: 0.33333333 | BI8: Redallyc | BJ8: 10
A9: Web of Science | B9: 491 | C9: =B9/B$10 -> 0.44474638 | D9: =C9*100% -> 0.44474638 | F9: 4 | G9: Nogueira J.; Rocha D.G.; Akerman M. | H9: Políticas públicas adoptadas en la pandemia de la COVID-19 en tres países de América Latina: contribuciones de la Promoción de la Salud para no volver al mundo que existía | I9: 2021 | J9: Global Health Promotion | K9: ='BASE DE DATOS SCOPUS'!L8 -> #N/A | L9: ='BASE DE DATOS SCOPUS'!Q8 -> 0 | N9: 2023 | O9: 9 | P9: 0.3 | Q9: 0.3 | S9: 2023 | T9: 9 | AA9: Total general | AB9: 2 | AC9: 1 | AD9: 1 | AF9: Total general | AG9: 2 | AM9: Peru | AN9: 12 | AO9: 0.4 | AP9: 0.4 | BD9: Total general | BE9: 30 | BF9: 1 | BG9: 1 | BI9: Total general | BJ9: 30
A10: Total | B10: =SUM(B8:B9) -> 1104 | C10: =SUM(C8:C9) -> 1 | D10: =SUM(D8:D9) -> 1 | F10: 5 | G10: da Cunha C.M.S.L.M.; Henriques M.A.P.; Costa A.C.J.S. | H10: Public health nursing: regulation and public health policies; [A enfermagem de saúde pública: regulação e políticas públicas de saúde]; [La enfermería de salud pública: regulación y las políticas públicas de salud] | I10: 2020 | J10: Revista Brasileira de Enfermagem | K10: ='BASE DE DATOS SCOPUS'!L9 -> #N/A | L10: ='BASE DE DATOS SCOPUS'!Q9 -> 0 | N10: Total general | O10: 30 | P10: 1 | Q10: 1 | S10: Total general | T10: 30 | AM10: United Kingdom | AN10: 2 | AO10: 0.066666667 | AP10: 0.066666667
F11: 6 | G11: Sanfrutos Velázquez N. | H11: La Finaciación de Los Servicios Regionales de Salud. Problemas y Posibles Soluciones | I11: 1991 | J11: Gaceta Sanitaria | K11: ='BASE DE DATOS SCOPUS'!L10 -> #N/A | L11: ='BASE DE DATOS SCOPUS'!Q10 -> 0 | AM11: Switzerland | AN11: 1 | AO11: 0.033333333 | AP11: 0.033333333
F12: 7 | G12: Gómez-Dantés O.; Frenk J. | H12: Chronicle of a century of public health in Mexico: From public health to social protection in health; [Crónica de un siglo de salud pública en México: De la salubridad pública a la protección social en salud] | I12: 2019 | J12: Salud Publica de Mexico | K12: ='BASE DE DATOS SCOPUS'!L11 -> #N/A | L12: ='BASE DE DATOS SCOPUS'!Q11 -> 0 | AM12: México | AN12: 1 | AO12: 0.033333333 | AP12: 0.033333333
F13: 8 | G13: Rivera O.; Benites S.; Mendigure J.; Bonilla C.A. | H13: Abandonment of therapy in multidrug-resistant tuberculosis: Associated factors in a region with a high burden of the disease in Perú; [Abandono del tratamiento en tuberculosis multirresistente: factores asociados en una región con alta carga de la enfermedad en Perú] | I13: 2019 | J13: Biomedica : revista del Instituto Nacional de Salud | K13: ='BASE DE DATOS SCOPUS'!L12 -> #N/A | L13: ='BASE DE DATOS SCOPUS'!Q12 -> 0 | AM13: Uganda | AN13: 1 | AO13: 0.033333333 | AP13: 0.033333333
F14: 9 | G14: Rodríguez-Arenas M.Á.; Martín-Ríos M.D.; Gil-Borrelli C. | H14: Public health interventions against hate violence; [Intervenciones en salud pública contra la violencia de odio] | I14: 2018 | J14: Gaceta Sanitaria | K14: ='BASE DE DATOS SCOPUS'!L13 -> #N/A | L14: ='BASE DE DATOS SCOPUS'!Q13 -> 0 | AM14: Ecuador | AN14: 1 | AO14: 0.033333333 | AP14: 0.033333333
F15: 10 | G15: Goigoechea Utrillo J.M.; Panella Ros J.; Portella Arguelaget E. | H15: Características del Tabaquismo en el Medio Escolar en Andorra | I15: 1992 | J15: Gaceta Sanitaria | K15: ='BASE DE DATOS SCOPUS'!L14 -> #N/A | L15: ='BASE DE DATOS SCOPUS'!Q14 -> 0 | AM15: Total general | AN15: 30 | AO15: 1 | AP15: 1
F16: 11 | G16: Valero C.; Nebot M.; Villalbí J.R. | H16: Embarazo en adolescentes en barcelona: distribución, antecedentes y consecuencias | I16: 1994 | J16: Gaceta Sanitaria | K16: ='BASE DE DATOS SCOPUS'!L15 -> #N/A | L16: ='BASE DE DATOS SCOPUS'!Q15 -> 0
F17: 12 | G17: dos Anjos V.Á.A.; Tavares G.H.; Ferreira J.S.; da Silva J.V.P.; da Costa F.R. | H17: Public health promotion policies and professional guidance in the Outdoor Gyms in Campo Grande/MS, Brazil; [Políticas públicas de promoção de saúde e orientação profissional em AAL em Campo Grande/MS, Brasil]; [Políticas de promoción de la salud pública y orientación profesional en AAL en Campo Grande/MS, Brasil] | I17: 2020 | J17: Retos | K17: ='BASE DE DATOS SCOPUS'!L16 -> #N/A | L17: ='BASE DE DATOS SCOPUS'!Q16 -> 0
F18: 13 | G18: Alves R.F.; Jiménez-Brobeil S.A.; Do Carmo Eulálio M.; De Andrade D.A.; Do Nascimento Cunha E.C.; Ferreira P.R.A. | H18: Public health interventions conducted by psychologists in Brazil, Spain and Portugal; [Intervenciones de psicólogos en la salud pública de Brasil, España y Portugal] | I18: 2016 | J18: Revista de Psicologia (Peru) | K18: ='BASE DE DATOS SCOPUS'!L17 -> #N/A | L18: ='BASE DE DATOS SCOPUS'!Q17 -> 0 | AN18: https://mapinseconds.com
F19: 14 | G19: Rodríguez R.; Márquez S.; López M. | H19: La perspectiva profesional en la reforma de la atención primaria de salud: una aproximación cualitativa | I19: 1995 | J19: Gaceta Sanitaria | K19: ='BASE DE DATOS SCOPUS'!L18 -> #N/A | L19: ='BASE DE DATOS SCOPUS'!Q18 -> 0
F20: 15 | G20: Santa María Juárez L.A. | H20: Public health interventions: Conceptual basis for the determination of objectives and evaluation; [Intervenciones en salud Pública: Bases Conceptuales Para La Determinación De Objetivos Y Evaluación] | I20: 2018 | J20: Revista Peruana de Medicina Experimental y Salud Publica | K20: ='BASE DE DATOS SCOPUS'!L19 -> #N/A | L20: ='BASE DE DATOS SCOPUS'!Q19 -> 0
A26: Base de datos | B26: Frecuencias
B27: Absoluta (n) | C27: Relativa (n/N) | D27: Porcentaje (%)
A28: Redalyc | B28: 6 | C28: =B28/B$34 -> 0.12 | D28: =C28/C$34 -> 0.12
A29: Scielo | B29: 11 | C29: =B29/B$34 -> 0.22 | D29: =C29*100% -> 0.22
A30: Google Académico | B30: 6 | C30: =B30/B$34 -> 0.12 | D30: =C30*100% -> 0.12
A31: Scopus | B31: 16 | C31: =B31/B$34 -> 0.32 | D31: =C31*100% -> 0.32
A32: ScienceDirect | B32: 5 | C32: =B32/B$34 -> 0.1 | D32: =C32*100% -> 0.1
A33: Web of Science (WoS). | B33: 6 | C33: =B33/B$34 -> 0.12 | D33: =C33*100% -> 0.12
A34: Total | B34: =SUM(B28:B33) -> 50 | C34: =SUM(C28:C33) -> 1 | D34: =SUM(D28:D33) -> 1

Sheet otros
A22: Caracteristicas | B22: Denominación | C22: f | D22: Porcentaje (%)
A23: Base de datos | B23: Redalyc | C23: 4 | D23: 0.13333333
B24: Scielo | C24: 6 | D24: 0.2
B25: Google Académico | C25: 5 | D25: 0.16666667
B26: Elsevier | C26: 5 | D26: 0.16666667
B27: ScienceDirect | C27: 5 | D27: 0.16666667
B28: Web of Science (WoS). | C28: 5 | D28: 0.16666667
A29: Revista | B29: International Journal of Environmental Research and Public Health | C29: 2 | D29: 0.066666667
B30: International Nursing Review | C30: 1 | D30: 0.033333333
B31: Perspectives on Sexual and Reproductive Health | C31: 1 | D31: 0.033333333
B32: Sexual and Reproductive Health Matters | C32: 1 | D32: 0.033333333
B33: Journal of Adolescent Health | C33: 2 | D33: 0.066666667
B34: Journal of Youth and Adolescence | C34: 1 | D34: 0.033333333
B35: Transactions of the Royal Society of Tropical Medicine and Hygiene | C35: 1 | D35: 0.033333333
B36: Reproductive Health | C36: 5 | D36: 0.16666667
B37: Fertility and Sterility | C37: 2 | D37: 0.066666667
B38: Nurse Education in Practice | C38: 1 | D38: 0.033333333
B39: BMC Public Health | C39: 1 | D39: 0.033333333
B40: BMJ Open | C40: 2 | D40: 0.066666667
B41: Journal of Cystic Fibrosis | C41: 1 | D41: 0.033333333
... B49: Hepatology | C49: 1 | D49: 0.033333333
B50: Andrology | C50: 1 | D50: 0.033333333 | F50: 30
B51: Piaís | C51: f | D51: Porcentaje (%)
B52: Ecuador | C52: 4 | D52: =C52/F$50 -> 0.13333333
B53: Perú | C53: 8 | D53: =C53/F$50 -> 0.26666667
B54: Brasil | C54: 12 | D54: =C54/F$50 -> 0.4
B55: Colombia | C55: 6 | D55: =C55/F$50 -> 0.2
B56: Accesibilidad
B57: Acesos libre | C57: 22 | D57: =C57/F$50 -> 0.73333333
B58: Acceso restrinjido | C58: 8 | D58: =C58/F$50 -> 0.26666667
B59: Enfoque
B60: Cuantitativo | C60: 21 | D60: =C60/F$50 -> 0.7
B61: Cualitativo | C61: 9 | D61: =C61/F$50 -> 0.3

Sheet PEGAR DATOS

Sheet IDENTIFICATION - REMOVED
A1: Authors | B1: Title | C1: Year | D1: Journal | E1: Abstract | F1: Keywords | G1: Publisher/Editorial | H1: Language | I1: Document Type | J1: DOI | K1: City of publication | L1: Country of study | M1: Scopus | N1: WOS | O1: DUPLICATED | P1: DOCUMENT TYPE | Q1: NOT ABSTRACT | R1: NOT DOI | S1: LANGUAGE
A2: ='BASE DE DATOS SCOPUS'!B5 -> #N/A | B2: ='BASE DE DATOS SCOPUS'!C5 -> #N/A | C2: ='BASE DE DATOS SCOPUS'!D5 -> #N/A | D2: ='BASE DE DATOS SCOPUS'!E5 -> #N/A | E2: ='BASE DE DATOS SCOPUS'!F5 -> #N/A | F2: ='BASE DE DATOS SCOPUS'!G5 -> #N/A | G2: ='BASE DE DATOS SCOPUS'!H5 -> #N/A | H2: ='BASE DE DATOS SCOPUS'!I5 -> #N/A | ... K2: ='BASE DE DATOS SCOPUS'!L5 -> #N/A | O2: no | P2: articulos | S2: =H2 -> #N/A
A3: ='BASE DE DATOS SCOPUS'!B6 -> #N/A | B3: ='BASE DE DATOS SCOPUS'!C6 -> #N/A | C3: ='BASE DE DATOS SCOPUS'!D6 -> #N/A | D3: ='BASE DE DATOS SCOPUS'!E6 -> #N/A | E3: ='BASE DE DATOS SCOPUS'!F6 -> #N/A | F3: ='BASE DE DATOS SCOPUS'!G6 -> #N/A | G3: ='BASE DE DATOS SCOPUS'!H6 -> #N/A | H3: ='BASE DE DATOS SCOPUS'!I6 -> #N/A | ... K3: ='BASE DE DATOS SCOPUS'!L6 -> #N/A | O3: no | P3: articulos
A4: ='BASE DE DATOS SCOPUS'!B7 -> #N/A | B4: ='BASE DE DATOS SCOPUS'!C7 -> #N/A | C4: ='BASE DE DATOS SCOPUS'!D7 -> #N/A | D4: ='BASE DE DATOS SCOPUS'!E7 -> #N/A | E4: ='BASE DE DATOS SCOPUS'!F7 -> #N/A | F4: ='BASE DE DATOS SCOPUS'!G7 -> #N/A | G4: ='BASE DE DATOS SCOPUS'!H7 -> #N/A | H4: ='BASE DE DATOS SCOPUS'!I7 -> #N/A | ... K4: ='BASE DE DATOS SCOPUS'!L7 -> #N/A | O4: no | P4: articulos
A5: ='BASE DE DATOS SCOPUS'!B8 -> #N/A | B5: ='BASE DE DATOS SCOPUS'!C8 -> #N/A | C5: ='BASE DE DATOS SCOPUS'!D8 -> #N/A | D5: ='BASE DE DATOS SCOPUS'!E8 -> #N/A | E5: ='BASE DE DATOS SCOPUS'!F8 -> #N/A | F5: ='BASE DE DATOS SCOPUS'!G8 -> #N/A | G5: ='BASE DE DATOS SCOPUS'!H8 -> #N/A | H5: ='BASE DE DATOS SCOPUS'!I8 -> #N/A | ... K5: ='BASE DE DATOS SCOPUS'!L8 -> #N/A | O5: no | P5: articulos
A6: ='BASE DE DATOS SCOPUS'!B9 -> #N/A | B6: ='BASE DE DATOS SCOPUS'!C9 -> #N/A | C6: ='BASE DE DATOS SCOPUS'!D9 -> #N/A | D6: ='BASE DE DATOS SCOPUS'!E9 -> #N/A | E6: ='BASE DE DATOS SCOPUS'!F9 -> #N/A | F6: ='BASE DE DATOS SCOPUS'!G9 -> #N/A | G6: ='BASE DE DATOS SCOPUS'!H9 -> #N/A | H6: ='BASE DE DATOS SCOPUS'!I9 -> #N/A | ... K6: ='BASE DE DATOS SCOPUS'!L9 -> #N/A | O6: no | P6: articulos
A7: ='BASE DE DATOS SCOPUS'!B10 -> #N/A | B7: ='BASE DE DATOS SCOPUS'!C10 -> #N/A | C7: ='BASE DE DATOS SCOPUS'!D10 -> #N/A | D7: ='BASE DE DATOS SCOPUS'!E10 -> #N/A | E7: ='BASE DE DATOS SCOPUS'!F10 -> #N/A | F7: ='BASE DE DATOS SCOPUS'!G10 -> #N/A | G7: ='BASE DE DATOS SCOPUS'!H10 -> #N/A | H7: ='BASE DE DATOS SCOPUS'!I10 -> #N/A | ... K7: ='BASE DE DATOS SCOPUS'!L10 -> #N/A | O7: no | P7: articulos
A8: ='BASE DE DATOS SCOPUS'!B11 -> #N/A | B8: ='BASE DE DATOS SCOPUS'!C11 -> #N/A | C8: ='BASE DE DATOS SCOPUS'!D11 -> #N/A | D8: ='BASE DE DATOS SCOPUS'!E11 -> #N/A | E8: ='BASE DE DATOS SCOPUS'!F11 -> #N/A | F8: ='BASE DE DATOS SCOPUS'!G11 -> #N/A | G8: ='BASE DE DATOS SCOPUS'!H11 -> #N/A | H8: ='BASE DE DATOS SCOPUS'!I11 -> #N/A | ... K8: ='BASE DE DATOS SCOPUS'!L11 -> #N/A | O8: no | P8: articulos
A9: ='BASE DE DATOS SCOPUS'!B12 -> #N/A | B9: ='BASE DE DATOS SCOPUS'!C12 -> #N/A | C9: ='BASE DE DATOS SCOPUS'!D12 -> #N/A | D9: ='BASE DE DATOS SCOPUS'!E12 -> #N/A | E9: ='BASE DE DATOS SCOPUS'!F12 -> #N/A | F9: ='BASE DE DATOS SCOPUS'!G12 -> #N/A | G9: ='BASE DE DATOS SCOPUS'!H12 -> #N/A | H9: ='BASE DE DATOS SCOPUS'!I12 -> #N/A | ... K9: ='BASE DE DATOS SCOPUS'!L12 -> #N/A | O9: no | P9: articulos
A10: ='BASE DE DATOS SCOPUS'!B13 -> #N/A | B10: ='BASE DE DATOS SCOPUS'!C13 -> #N/A | C10: ='BASE DE DATOS SCOPUS'!D13 -> #N/A | D10: ='BASE DE DATOS SCOPUS'!E13 -> #N/A | E10: ='BASE DE DATOS SCOPUS'!F13 -> #N/A | F10: ='BASE DE DATOS SCOPUS'!G13 -> #N/A | G10: ='BASE DE DATOS SCOPUS'!H13 -> #N/A | H10: ='BASE DE DATOS SCOPUS'!I13 -> #N/A | ... K10: ='BASE DE DATOS SCOPUS'!L13 -> #N/A | O10: no | P10: articulos
A11: ='BASE DE DATOS SCOPUS'!B14 -> #N/A | B11: ='BASE DE DATOS SCOPUS'!C14 -> #N/A | C11: ='BASE DE DATOS SCOPUS'!D14 -> #N/A | D11: ='BASE DE DATOS SCOPUS'!E14 -> #N/A | E11: ='BASE DE DATOS SCOPUS'!F14 -> #N/A | F11: ='BASE DE DATOS SCOPUS'!G14 -> #N/A | G11: ='BASE DE DATOS SCOPUS'!H14 -> #N/A | H11: ='BASE DE DATOS SCOPUS'!I14 -> #N/A | ... K11: ='BASE DE DATOS SCOPUS'!L14 -> #N/A | O11: no | P11: articulos
A12: ='BASE DE DATOS SCOPUS'!B15 -> #N/A | B12: ='BASE DE DATOS SCOPUS'!C15 -> #N/A | C12: ='BASE DE DATOS SCOPUS'!D15 -> #N/A | D12: ='BASE DE DATOS SCOPUS'!E15 -> #N/A | E12: ='BASE DE DATOS SCOPUS'!F15 -> #N/A | F12: ='BASE DE DATOS SCOPUS'!G15 -> #N/A | G12: ='BASE DE DATOS SCOPUS'!H15 -> #N/A | H12: ='BASE DE DATOS SCOPUS'!I15 -> #N/A | ... K12: ='BASE DE DATOS SCOPUS'!L15 -> #N/A | O12: no | P12: articulos
A13: ='BASE DE DATOS SCOPUS'!B16 -> #N/A | B13: ='BASE DE DATOS SCOPUS'!C16 -> #N/A | C13: ='BASE DE DATOS SCOPUS'!D16 -> #N/A | D13: ='BASE DE DATOS SCOPUS'!E16 -> #N/A | E13: ='BASE DE DATOS SCOPUS'!F16 -> #N/A | F13: ='BASE DE DATOS SCOPUS'!G16 -> #N/A | G13: ='BASE DE DATOS SCOPUS'!H16 -> #N/A | H13: ='BASE DE DATOS SCOPUS'!I16 -> #N/A | ... K13: ='BASE DE DATOS SCOPUS'!L16 -> #N/A | O13: no | P13: articulos
A14: ='BASE DE DATOS SCOPUS'!B17 -> #N/A | B14: ='BASE DE DATOS SCOPUS'!C17 -> #N/A | C14: ='BASE DE DATOS SCOPUS'!D17 -> #N/A | D14: ='BASE DE DATOS SCOPUS'!E17 -> #N/A | E14: ='BASE DE DATOS SCOPUS'!F17 -> #N/A | F14: ='BASE DE DATOS SCOPUS'!G17 -> #N/A | G14: ='BASE DE DATOS SCOPUS'!H17 -> #N/A | H14: ='BASE DE DATOS SCOPUS'!I17 -> #N/A | ... K14: ='BASE DE DATOS SCOPUS'!L17 -> #N/A | O14: no | P14: articulos
... A1000: ='BASE DE DATOS SCOPUS'!B1003 -> #N/A | B1000: ='BASE DE DATOS SCOPUS'!C1003 -> #N/A | C1000: ='BASE DE DATOS SCOPUS'!D1003 -> #N/A | D1000: ='BASE DE DATOS SCOPUS'!E1003 -> #N/A | E1000: ='BASE DE DATOS SCOPUS'!F1003 -> #N/A | F1000: ='BASE DE DATOS SCOPUS'!G1003 -> #N/A | G1000: ='BASE DE DATOS SCOPUS'!H1003 -> #N/A | H1000: ='BASE DE DATOS SCOPUS'!I1003 -> #N/A | ... K1000: ='BASE DE DATOS SCOPUS'!L1003 -> #N/A | O1000: no | P1000: articulos

Sheet SCREENING - EXCLUDED
A1: Authors | B1: Title | C1: Year | D1: Journal | E1: Abstract | F1: Keywords | G1: Publisher/Editorial | H1: Language | I1: Document Type | J1: DOI | K1: City of publication | L1: Country of study | M1: Scopus | N1: WOS | O1: Evaluador 1 ¿Quién? | P1: Luego de revisar el resumen ¿El artículo está referido al objetivo de la RSL? | Q1: Evaluador 2 ¿Quién? | R1: Luego de revisar el resumen ¿El artículo está referido al objetivo de la RSL? | S1: Decisión final ¿Se incluye el documento? (evaluación de pares ciego) | T1: OBSERVACIÓN 1 ¿Por qué se eliminó el documento?
A2: ='IDENTIFICATION - REMOVED'!A2 -> #N/A | B2: ='IDENTIFICATION - REMOVED'!B2 -> #N/A | C2: ='IDENTIFICATION - REMOVED'!C2 -> #N/A | D2: ='IDENTIFICATION - REMOVED'!D2 -> #N/A | E2: ='IDENTIFICATION - REMOVED'!E2 -> #N/A | F2: ='IDENTIFICATION - REMOVED'!F2 -> #N/A | G2: ='IDENTIFICATION - REMOVED'!G2 -> #N/A | H2: ='IDENTIFICATION - REMOVED'!H2 -> #N/A | ... L2: ='IDENTIFICATION - REMOVED'!L2 -> 0 | M2: ='IDENTIFICATION - REMOVED'!M4 -> 0 | N2: ='IDENTIFICATION - REMOVED'!N4 -> 0 | O2: X | P2: Yes | Q2: Y | R2: Yes | S2: Yes
A3: ='IDENTIFICATION - REMOVED'!A3 -> #N/A | B3: ='IDENTIFICATION - REMOVED'!B3 -> #N/A | C3: ='IDENTIFICATION - REMOVED'!C3 -> #N/A | D3: ='IDENTIFICATION - REMOVED'!D3 -> #N/A | E3: ='IDENTIFICATION - REMOVED'!E3 -> #N/A | F3: ='IDENTIFICATION - REMOVED'!F3 -> #N/A | G3: ='IDENTIFICATION - REMOVED'!G3 -> #N/A | H3: ='IDENTIFICATION - REMOVED'!H3 -> #N/A | ... L3: ='IDENTIFICATION - REMOVED'!L3 -> 0 | M3: ='IDENTIFICATION - REMOVED'!M5 -> 0 | N3: ='IDENTIFICATION - REMOVED'!N5 -> 0 | O3: X | P3: Probably | Q3: Y | R3: Probably | S3: Yes
A4: ='IDENTIFICATION - REMOVED'!A4 -> #N/A | B4: ='IDENTIFICATION - REMOVED'!B4 -> #N/A | C4: ='IDENTIFICATION - REMOVED'!C4 -> #N/A | D4: ='IDENTIFICATION - REMOVED'!D4 -> #N/A | E4: ='IDENTIFICATION - REMOVED'!E4 -> #N/A | F4: ='IDENTIFICATION - REMOVED'!F4 -> #N/A | G4: ='IDENTIFICATION - REMOVED'!G4 -> #N/A | H4: ='IDENTIFICATION - REMOVED'!H4 -> #N/A | ... L4: ='IDENTIFICATION - REMOVED'!L4 -> 0 | M4: ='IDENTIFICATION - REMOVED'!M6 -> 0 | N4: ='IDENTIFICATION - REMOVED'!N6 -> 0 | O4: X | P4: Probably | Q4: Y | R4: Probably | S4: Yes
A5: ='IDENTIFICATION - REMOVED'!A5 -> #N/A | B5: ='IDENTIFICATION - REMOVED'!B5 -> #N/A | C5: ='IDENTIFICATION - REMOVED'!C5 -> #N/A | D5: ='IDENTIFICATION - REMOVED'!D5 -> #N/A | E5: ='IDENTIFICATION - REMOVED'!E5 -> #N/A | F5: ='IDENTIFICATION - REMOVED'!F5 -> #N/A | G5: ='IDENTIFICATION - REMOVED'!G5 -> #N/A | H5: ='IDENTIFICATION - REMOVED'!H5 -> #N/A | ... L5: ='IDENTIFICATION - REMOVED'!L5 -> 0 | M5: ='IDENTIFICATION - REMOVED'!M7 -> 0 | N5: ='IDENTIFICATION - REMOVED'!N7 -> 0 | O5: X | P5: Yes | Q5: Y | R5: Yes | S5: Yes
A6: ='IDENTIFICATION - REMOVED'!A6 -> #N/A | B6: ='IDENTIFICATION - REMOVED'!B6 -> #N/A | C6: ='IDENTIFICATION - REMOVED'!C6 -> #N/A | D6: ='IDENTIFICATION - REMOVED'!D6 -> #N/A | E6: ='IDENTIFICATION - REMOVED'!E6 -> #N/A | F6: ='IDENTIFICATION - REMOVED'!F6 -> #N/A | G6: ='IDENTIFICATION - REMOVED'!G6 -> #N/A | H6: ='IDENTIFICATION - REMOVED'!H6 -> #N/A | ... L6: ='IDENTIFICATION - REMOVED'!L6 -> 0 | M6: ='IDENTIFICATION - REMOVED'!M8 -> 0 | N6: ='IDENTIFICATION - REMOVED'!N8 -> 0 | O6: X | P6: Probably | Q6: Y | R6: Probably | S6: Yes
A7: ='IDENTIFICATION - REMOVED'!A7 -> #N/A | B7: ='IDENTIFICATION - REMOVED'!B7 -> #N/A | C7: ='IDENTIFICATION - REMOVED'!C7 -> #N/A | D7: ='IDENTIFICATION - REMOVED'!D7 -> #N/A | E7: ='IDENTIFICATION - REMOVED'!E7 -> #N/A | F7: ='IDENTIFICATION - REMOVED'!F7 -> #N/A | G7: ='IDENTIFICATION - REMOVED'!G7 -> #N/A | H7: ='IDENTIFICATION - REMOVED'!H7 -> #N/A | ... L7: ='IDENTIFICATION - REMOVED'!L7 -> 0 | M7: ='IDENTIFICATION - REMOVED'!M9 -> 0 | N7: ='IDENTIFICATION - REMOVED'!N9 -> 0 | O7: X | P7: Probably | Q7: Y | R7: Yes | S7: Yes
A8: ='IDENTIFICATION - REMOVED'!A8 -> #N/A | B8: ='IDENTIFICATION - REMOVED'!B8 -> #N/A | C8: ='IDENTIFICATION - REMOVED'!C8 -> #N/A | D8: ='IDENTIFICATION - REMOVED'!D8 -> #N/A | E8: ='IDENTIFICATION - REMOVED'!E8 -> #N/A | F8: ='IDENTIFICATION - REMOVED'!F8 -> #N/A | G8: ='IDENTIFICATION - REMOVED'!G8 -> #N/A | H8: ='IDENTIFICATION - REMOVED'!H8 -> #N/A | ... L8: ='IDENTIFICATION - REMOVED'!L8 -> 0 | M8: ='IDENTIFICATION - REMOVED'!M10 -> 0 | N8: ='IDENTIFICATION - REMOVED'!N10 -> 0 | O8: X | P8: Yes | Q8: Y | R8: Yes | S8: Yes
A9: ='IDENTIFICATION - REMOVED'!A9 -> #N/A | B9: ='IDENTIFICATION - REMOVED'!B9 -> #N/A | C9: ='IDENTIFICATION - REMOVED'!C9 -> #N/A | D9: ='IDENTIFICATION - REMOVED'!D9 -> #N/A | E9: ='IDENTIFICATION - REMOVED'!E9 -> #N/A | F9: ='IDENTIFICATION - REMOVED'!F9 -> #N/A | G9: ='IDENTIFICATION - REMOVED'!G9 -> #N/A | H9: ='IDENTIFICATION - REMOVED'!H9 -> #N/A | ... L9: ='IDENTIFICATION - REMOVED'!L9 -> 0 | M9: ='IDENTIFICATION - REMOVED'!M11 -> 0 | N9: ='IDENTIFICATION - REMOVED'!N11 -> 0 | O9: X | P9: Probably | Q9: Y | R9: Probably | S9: Yes
A10: ='IDENTIFICATION - REMOVED'!A10 -> #N/A | B10: ='IDENTIFICATION - REMOVED'!B10 -> #N/A | C10: ='IDENTIFICATION - REMOVED'!C10 -> #N/A | D10: ='IDENTIFICATION - REMOVED'!D10 -> #N/A | E10: ='IDENTIFICATION - REMOVED'!E10 -> #N/A | F10: ='IDENTIFICATION - REMOVED'!F10 -> #N/A | G10: ='IDENTIFICATION - REMOVED'!G10 -> #N/A | H10: ='IDENTIFICATION - REMOVED'!H10 -> #N/A | ... L10: ='IDENTIFICATION - REMOVED'!L10 -> 0 | M10: ='IDENTIFICATION - REMOVED'!M12 -> 0 | N10: ='IDENTIFICATION - REMOVED'!N12 -> 0 | O10: X | P10: Yes | Q10: Y | R10: Yes | S10: Yes
A11: ='IDENTIFICATION - REMOVED'!A11 -> #N/A | B11: ='IDENTIFICATION - REMOVED'!B11 -> #N/A | C11: ='IDENTIFICATION - REMOVED'!C11 -> #N/A | D11: ='IDENTIFICATION - REMOVED'!D11 -> #N/A | E11: ='IDENTIFICATION - REMOVED'!E11 -> #N/A | F11: ='IDENTIFICATION - REMOVED'!F11 -> #N/A | G11: ='IDENTIFICATION - REMOVED'!G11 -> #N/A | H11: ='IDENTIFICATION - REMOVED'!H11 -> #N/A | ... L11: ='IDENTIFICATION - REMOVED'!L11 -> 0 | M11: ='IDENTIFICATION - REMOVED'!M13 -> 0 | N11: ='IDENTIFICATION - REMOVED'!N13 -> 0 | O11: X | P11: Probably | Q11: Y | R11: Yes | S11: Yes
A12: ='IDENTIFICATION - REMOVED'!A12 -> #N/A | B12: ='IDENTIFICATION - REMOVED'!B12 -> #N/A | C12: ='IDENTIFICATION - REMOVED'!C12 -> #N/A | D12: ='IDENTIFICATION - REMOVED'!D12 -> #N/A | E12: ='IDENTIFICATION - REMOVED'!E12 -> #N/A | F12: ='IDENTIFICATION - REMOVED'!F12 -> #N/A | G12: ='IDENTIFICATION - REMOVED'!G12 -> #N/A | H12: ='IDENTIFICATION - REMOVED'!H12 -> #N/A | ... L12: ='IDENTIFICATION - REMOVED'!L12 -> 0 | M12: ='IDENTIFICATION - REMOVED'!M14 -> 0 | N12: ='IDENTIFICATION - REMOVED'!N14 -> 0 | O12: X | P12: Yes | Q12: Y | R12: Yes | S12: Yes
A13: ='IDENTIFICATION - REMOVED'!A13 -> #N/A | B13: ='IDENTIFICATION - REMOVED'!B13 -> #N/A | C13: ='IDENTIFICATION - REMOVED'!C13 -> #N/A | D13: ='IDENTIFICATION - REMOVED'!D13 -> #N/A | E13: ='IDENTIFICATION - REMOVED'!E13 -> #N/A | F13: ='IDENTIFICATION - REMOVED'!F13 -> #N/A | G13: ='IDENTIFICATION - REMOVED'!G13 -> #N/A | H13: ='IDENTIFICATION - REMOVED'!H13 -> #N/A | ... L13: ='IDENTIFICATION - REMOVED'!L13 -> 0 | M13: ='IDENTIFICATION - REMOVED'!M15 -> 0 | N13: ='IDENTIFICATION - REMOVED'!N15 -> 0 | O13: X | P13: Probably | Q13: Y | R13: Yes | S13: Yes
... A91: ='IDENTIFICATION - REMOVED'!A91 -> #N/A | B91: ='IDENTIFICATION - REMOVED'!B91 -> #N/A | C91: ='IDENTIFICATION - REMOVED'!C91 -> #N/A | D91: ='IDENTIFICATION - REMOVED'!D91 -> #N/A | E91: ='IDENTIFICATION - REMOVED'!E91 -> #N/A | F91: ='IDENTIFICATION - REMOVED'!F91 -> #N/A | G91: ='IDENTIFICATION - REMOVED'!G91 -> #N/A | H91: ='IDENTIFICATION - REMOVED'!H91 -> #N/A | ... L91: ='IDENTIFICATION - REMOVED'!L91 -> 0 | M91: ='IDENTIFICATION - REMOVED'!M93 -> 0 | N91: ='IDENTIFICATION - REMOVED'!N93 -> 0 | O91: X | P91: Probably | Q91: Y | R91: Probably | S91: Yes
A92: ='IDENTIFICATION - REMOVED'!A92 -> #N/A | B92: ='IDENTIFICATION - REMOVED'!B92 -> #N/A | C92: ='IDENTIFICATION - REMOVED'!C92 -> #N/A | D92: ='IDENTIFICATION - REMOVED'!D92 -> #N/A | E92: ='IDENTIFICATION - REMOVED'!E92 -> #N/A | F92: ='IDENTIFICATION - REMOVED'!F92 -> #N/A | G92: ='IDENTIFICATION - REMOVED'!G92 -> #N/A | H92: ='IDENTIFICATION - REMOVED'!H92 -> #N/A | ... L92: ='IDENTIFICATION - REMOVED'!L92 -> 0 | M92: ='IDENTIFICATION - REMOVED'!M94 -> 0 | N92: ='IDENTIFICATION - REMOVED'!N94 -> 0 | O92: X | P92: Yes | Q92: Y | R92: Yes | S92: Not | T92: Contenido controversial y divisivo innecesario.
A93: ='IDENTIFICATION - REMOVED'!A93 -> #N/A | B93: ='IDENTIFICATION - REMOVED'!B93 -> #N/A | C93: ='IDENTIFICATION - REMOVED'!C93 -> #N/A | D93: ='IDENTIFICATION - REMOVED'!D93 -> #N/A | E93: ='IDENTIFICATION - REMOVED'!E93 -> #N/A | F93: ='IDENTIFICATION - REMOVED'!F93 -> #N/A | G93: ='IDENTIFICATION - REMOVED'!G93 -> #N/A | H93: ='IDENTIFICATION - REMOVED'!H93 -> #N/A | ... L93: ='IDENTIFICATION - REMOVED'!L93 -> 0 | M93: ='IDENTIFICATION - REMOVED'!M95 -> 0 | N93: ='IDENTIFICATION - REMOVED'!N95 -> 0 | O93: X | P93: Probably | Q93: Y | R93: Probably | S93: Not | T93: Costos elevados para incluirlo.
A94: ='IDENTIFICATION - REMOVED'!A94 -> #N/A | B94: ='IDENTIFICATION - REMOVED'!B94 -> #N/A | C94: ='IDENTIFICATION - REMOVED'!C94 -> #N/A | D94: ='IDENTIFICATION - REMOVED'!D94 -> #N/A | E94: ='IDENTIFICATION - REMOVED'!E94 -> #N/A | F94: ='IDENTIFICATION - REMOVED'!F94 -> #N/A | G94: ='IDENTIFICATION - REMOVED'!G94 -> #N/A | H94: ='IDENTIFICATION - REMOVED'!H94 -> #N/A | ... L94: ='IDENTIFICATION - REMOVED'!L94 -> 0 | M94: ='IDENTIFICATION - REMOVED'!M96 -> 0 | N94: ='IDENTIFICATION - REMOVED'!N96 -> 0 | O94: X | P94: Yes | Q94: Y | R94: Yes | S94: Not | T94: Problemas de accesibilidad y distribución.
A95: ='IDENTIFICATION - REMOVED'!A95 -> #N/A | B95: ='IDENTIFICATION - REMOVED'!B95 -> #N/A | C95: ='IDENTIFICATION - REMOVED'!C95 -> #N/A | D95: ='IDENTIFICATION - REMOVED'!D95 -> #N/A | E95: ='IDENTIFICATION - REMOVED'!E95 -> #N/A | F95: ='IDENTIFICATION - REMOVED'!F95 -> #N/A | G95: ='IDENTIFICATION - REMOVED'!G95 -> #N/A | H95: ='IDENTIFICATION - REMOVED'!H95 -> #N/A | ... L95: ='IDENTIFICATION - REMOVED'!L95 -> 0 | M95: ='IDENTIFICATION - REMOVED'!M97 -> 0 | N95: ='IDENTIFICATION - REMOVED'!N97 -> 0 | O95: X | P95: Probably | Q95: Y | R95: Probably | S95: Not | T95: Complejidad excesiva para el público.
A96: ='IDENTIFICATION - REMOVED'!A96 -> #N/A | B96: ='IDENTIFICATION - REMOVED'!B96 -> #N/A | C96: ='IDENTIFICATION - REMOVED'!C96 -> #N/A | D96: ='IDENTIFICATION - REMOVED'!D96 -> #N/A | E96: ='IDENTIFICATION - REMOVED'!E96 -> #N/A | F96: ='IDENTIFICATION - REMOVED'!F96 -> #N/A | G96: ='IDENTIFICATION - REMOVED'!G96 -> #N/A | H96: ='IDENTIFICATION - REMOVED'!H96 -> #N/A | ... L96: ='IDENTIFICATION - REMOVED'!L96 -> 0 | M96: ='IDENTIFICATION - REMOVED'!M98 -> 0 | N96: ='IDENTIFICATION - REMOVED'!N98 -> 0 | O96: X | P96: Yes | Q96: Y | R96: Yes | S96: Not | T96: Contenía información confidencial sensible.
A97: ='IDENTIFICATION - REMOVED'!A97 -> #N/A | B97: ='IDENTIFICATION - REMOVED'!B97 -> #N/A | C97: ='IDENTIFICATION - REMOVED'!C97 -> #N/A | D97: ='IDENTIFICATION - REMOVED'!D97 -> #N/A | E97: ='IDENTIFICATION - REMOVED'!E97 -> #N/A | F97: ='IDENTIFICATION - REMOVED'!F97 -> #N/A | G97: ='IDENTIFICATION - REMOVED'!G97 -> #N/A | H97: ='IDENTIFICATION - REMOVED'!H97 -> #N/A | ... L97: ='IDENTIFICATION - REMOVED'!L97 -> 0 | M97: ='IDENTIFICATION - REMOVED'!M99 -> 0 | N97: ='IDENTIFICATION - REMOVED'!N99 -> 0 | O97: X | P97: Probably | Q97: Y | R97: Probably | S97: Not | T97: Relevancia limitada para el propósito.
A98: ='IDENTIFICATION - REMOVED'!A98 -> #N/A | B98: ='IDENTIFICATION - REMOVED'!B98 -> #N/A | C98: ='IDENTIFICATION - REMOVED'!C98 -> #N/A | D98: ='IDENTIFICATION - REMOVED'!D98 -> #N/A | E98: ='IDENTIFICATION - REMOVED'!E98 -> #N/A | F98: ='IDENTIFICATION - REMOVED'!F98 -> #N/A | G98: ='IDENTIFICATION - REMOVED'!G98 -> #N/A | H98: ='IDENTIFICATION - REMOVED'!H98 -> #N/A | ... L98: ='IDENTIFICATION - REMOVED'!L98 -> 0 | M98: ='IDENTIFICATION - REMOVED'!M100 -> 0 | N98: ='IDENTIFICATION - REMOVED'!N100 -> 0 | O98: X | P98: Probably | Q98: Y | R98: Probably | S98: Not | T98: Falta de originalidad evidente.
A99: ='IDENTIFICATION - REMOVED'!A99 -> #N/A | B99: ='IDENTIFICATION - REMOVED'!B99 -> #N/A | C99: ='IDENTIFICATION - REMOVED'!C99 -> #N/A | D99: ='IDENTIFICATION - REMOVED'!D99 -> #N/A | E99: ='IDENTIFICATION - REMOVED'!E99 -> #N/A | F99: ='IDENTIFICATION - REMOVED'!F99 -> #N/A | G99: ='IDENTIFICATION - REMOVED'!G99 -> #N/A | H99: ='IDENTIFICATION - REMOVED'!H99 -> #N/A | ... L99: ='IDENTIFICATION - REMOVED'!L99 -> 0 | M99: ='IDENTIFICATION - REMOVED'!M101 -> 0 | N99: ='IDENTIFICATION - REMOVED'!N101 -> 0 | O99: X | P99: Yes | Q99: Y | R99: Yes | S99: Not | T99: Potencial para malinterpretaciones serias.
A100: ='IDENTIFICATION - REMOVED'!A100 -> #N/A | B100: ='IDENTIFICATION - REMOVED'!B100 -> #N/A | C100: ='IDENTIFICATION - REMOVED'!C100 -> #N/A | D100: ='IDENTIFICATION - REMOVED'!D100 -> #N/A | E100: ='IDENTIFICATION - REMOVED'!E100 -> #N/A | F100: ='IDENTIFICATION - REMOVED'!F100 -> #N/A | G100: ='IDENTIFICATION - REMOVED'!G100 -> #N/A | H100: ='IDENTIFICATION - REMOVED'!H100 -> #N/A | ... L100: ='IDENTIFICATION - REMOVED'!L100 -> 0 | M100: ='IDENTIFICATION - REMOVED'!M102 -> 0 | N100: ='IDENTIFICATION - REMOVED'!N102 -> 0 | O100: X | P100: Yes | Q100: Y | R100: Yes | S100: Not | T100: Inconsistencias en los datos encontrados.
A101: ='IDENTIFICATION - REMOVED'!A101 -> #N/A | B101: ='IDENTIFICATION - REMOVED'!B101 -> #N/A | C101: ='IDENTIFICATION - REMOVED'!C101 -> #N/A | D101: ='IDENTIFICATION - REMOVED'!D101 -> #N/A | E101: ='IDENTIFICATION - REMOVED'!E101 -> #N/A | F101: ='IDENTIFICATION - REMOVED'!F101 -> #N/A | G101: ='IDENTIFICATION - REMOVED'!G101 -> #N/A | H101: ='IDENTIFICATION - REMOVED'!H101 -> #N/A | ... L101: ='IDENTIFICATION - REMOVED'!L101 -> 0 | M101: ='IDENTIFICATION - REMOVED'!M103 -> 0 | N101: ='IDENTIFICATION - REMOVED'!N103 -> 0 | O101: X | P101: Probably | Q101: Y | R101: Probably | S101: Not | T101: Longitud excesiva y sin enfoque.
A102: ='IDENTIFICATION - REMOVED'!A102 -> #N/A | B102: ='IDENTIFICATION - REMOVED'!B102 -> #N/A | C102: ='IDENTIFICATION - REMOVED'!C102 -> #N/A | D102: ='IDENTIFICATION - REMOVED'!D102 -> #N/A | E102: ='IDENTIFICATION - REMOVED'!E102 -> #N/A | F102: ='IDENTIFICATION - REMOVED'!F102 -> #N/A | G102: ='IDENTIFICATION - REMOVED'!G102 -> #N/A | H102: ='IDENTIFICATION - REMOVED'!H102 -> #N/A | ... L102: ='IDENTIFICATION - REMOVED'!L102 -> 0 | M102: ='IDENTIFICATION - REMOVED'!M104 -> 0 | N102: ='IDENTIFICATION - REMOVED'!N104 -> 0 | O102: X | P102: Probably | Q102: Y | R102: Probably | S102: Not | T102: Contenido controversial y divisivo innecesario.
A103: ='IDENTIFICATION - REMOVED'!A103 -> #N/A | B103: ='IDENTIFICATION - REMOVED'!B103 -> #N/A | C103: ='IDENTIFICATION - REMOVED'!C103 -> #N/A | D103: ='IDENTIFICATION - REMOVED'!D103 -> #N/A | E103: ='IDENTIFICATION - REMOVED'!E103 -> #N/A | F103: ='IDENTIFICATION - REMOVED'!F103 -> #N/A | G103: ='IDENTIFICATION - REMOVED'!G103 -> #N/A | H103: ='IDENTIFICATION - REMOVED'!H103 -> #N/A | ... L103: ='IDENTIFICATION - REMOVED'!L103 -> 0 | M103: ='IDENTIFICATION - REMOVED'!M105 -> 0 | N103: ='IDENTIFICATION - REMOVED'!N105 -> 0 | O103: X | P103: Yes | Q103: Y | R103: Yes | S103: Not | T103: Carecía de fuentes confiables mencionadas.
... A1000: ='IDENTIFICATION - REMOVED'!A1000 -> #N/A | B1000: ='IDENTIFICATION - REMOVED'!B1000 -> #N/A | C1000: ='IDENTIFICATION - REMOVED'!C1000 -> #N/A | D1000: ='IDENTIFICATION - REMOVED'!D1000 -> #N/A | E1000: ='IDENTIFICATION - REMOVED'!E1000 -> #N/A | F1000: ='IDENTIFICATION - REMOVED'!F1000 -> #N/A | G1000: ='IDENTIFICATION - REMOVED'!G1000 -> #N/A | H1000: ='IDENTIFICATION - REMOVED'!H1000 -> #N/A | ... L1000: ='IDENTIFICATION - REMOVED'!L1000 -> 0 | M1000: ='IDENTIFICATION - REMOVED'!M1002 -> 0 | N1000: ='IDENTIFICATION - REMOVED'!N1002 -> 0 | O1000: X | P1000: Probably | Q1000: Y | R1000: Not | S1000: Not | T1000: Complejidad excesiva para el público.

Sheet SCREENING - RETRIEVED
A1: Authors | B1: Title | C1: Year | D1: Journal | E1: Abstract | F1: Keywords | G1: Publisher/Editorial | H1: Language | I1: Document Type | J1: Cited by | K1: DOI | L1: City of publication | M1: Country of study | N1: Scopus | O1: WOS | P1: ¿Documento recuperado? | Q1: OBSERVACIÓN 2 ¿Por qué no se pudo recuperar el documento?
A2: ='SCREENING - EXCLUDED'!A2 -> #N/A | B2: ='SCREENING - EXCLUDED'!B2 -> #N/A | C2: ='SCREENING - EXCLUDED'!C2 -> #N/A | D2: ='SCREENING - EXCLUDED'!D2 -> #N/A | E2: ='SCREENING - EXCLUDED'!E2 -> #N/A | F2: ='SCREENING - EXCLUDED'!F2 -> #N/A | G2: ='SCREENING - EXCLUDED'!G2 -> #N/A | H2: ='SCREENING - EXCLUDED'!H2 -> #N/A | ... M2: ='SCREENING - EXCLUDED'!M2 -> 0 | N2: X | P2: Yes
A3: ='SCREENING - EXCLUDED'!A3 -> #N/A | B3: ='SCREENING - EXCLUDED'!B3 -> #N/A | C3: ='SCREENING - EXCLUDED'!C3 -> #N/A | D3: ='SCREENING - EXCLUDED'!D3 -> #N/A | E3: ='SCREENING - EXCLUDED'!E3 -> #N/A | F3: ='SCREENING - EXCLUDED'!F3 -> #N/A | G3: ='SCREENING - EXCLUDED'!G3 -> #N/A | H3: ='SCREENING - EXCLUDED'!H3 -> #N/A | ... M3: ='SCREENING - EXCLUDED'!M3 -> 0 | N3: X | P3: Yes
A4: ='SCREENING - EXCLUDED'!A4 -> #N/A | B4: ='SCREENING - EXCLUDED'!B4 -> #N/A | C4: ='SCREENING - EXCLUDED'!C4 -> #N/A | D4: ='SCREENING - EXCLUDED'!D4 -> #N/A | E4: ='SCREENING - EXCLUDED'!E4 -> #N/A | F4: ='SCREENING - EXCLUDED'!F4 -> #N/A | G4: ='SCREENING - EXCLUDED'!G4 -> #N/A | H4: ='SCREENING - EXCLUDED'!H4 -> #N/A | ... M4: ='SCREENING - EXCLUDED'!M4 -> 0 | N4: X | P4: Yes
A5: ='SCREENING - EXCLUDED'!A5 -> #N/A | B5: ='SCREENING - EXCLUDED'!B5 -> #N/A | C5: ='SCREENING - EXCLUDED'!C5 -> #N/A | D5: ='SCREENING - EXCLUDED'!D5 -> #N/A | E5: ='SCREENING - EXCLUDED'!E5 -> #N/A | F5: ='SCREENING - EXCLUDED'!F5 -> #N/A | G5: ='SCREENING - EXCLUDED'!G5 -> #N/A | H5: ='SCREENING - EXCLUDED'!H5 -> #N/A | ... M5: ='SCREENING - EXCLUDED'!M5 -> 0 | N5: X | P5: Yes
A6: ='SCREENING - EXCLUDED'!A6 -> #N/A | B6: ='SCREENING - EXCLUDED'!B6 -> #N/A | C6: ='SCREENING - EXCLUDED'!C6 -> #N/A | D6: ='SCREENING - EXCLUDED'!D6 -> #N/A | E6: ='SCREENING - EXCLUDED'!E6 -> #N/A | F6: ='SCREENING - EXCLUDED'!F6 -> #N/A | G6: ='SCREENING - EXCLUDED'!G6 -> #N/A | H6: ='SCREENING - EXCLUDED'!H6 -> #N/A | ... M6: ='SCREENING - EXCLUDED'!M6 -> 0 | N6: X | P6: Yes
A7: ='SCREENING - EXCLUDED'!A7 -> #N/A | B7: ='SCREENING - EXCLUDED'!B7 -> #N/A | C7: ='SCREENING - EXCLUDED'!C7 -> #N/A | D7: ='SCREENING - EXCLUDED'!D7 -> #N/A | E7: ='SCREENING - EXCLUDED'!E7 -> #N/A | F7: ='SCREENING - EXCLUDED'!F7 -> #N/A | G7: ='SCREENING - EXCLUDED'!G7 -> #N/A | H7: ='SCREENING - EXCLUDED'!H7 -> #N/A | ... M7: ='SCREENING - EXCLUDED'!M7 -> 0 | N7: X | P7: Yes
A8: ='SCREENING - EXCLUDED'!A8 -> #N/A | B8: ='SCREENING - EXCLUDED'!B8 -> #N/A | C8: ='SCREENING - EXCLUDED'!C8 -> #N/A | D8: ='SCREENING - EXCLUDED'!D8 -> #N/A | E8: ='SCREENING - EXCLUDED'!E8 -> #N/A | F8: ='SCREENING - EXCLUDED'!F8 -> #N/A | G8: ='SCREENING - EXCLUDED'!G8 -> #N/A | H8: ='SCREENING - EXCLUDED'!H8 -> #N/A | ... M8: ='SCREENING - EXCLUDED'!M8 -> 0 | N8: X | P8: Yes
A9: ='SCREENING - EXCLUDED'!A9 -> #N/A | B9: ='SCREENING - EXCLUDED'!B9 -> #N/A | C9: ='SCREENING - EXCLUDED'!C9 -> #N/A | D9: ='SCREENING - EXCLUDED'!D9 -> #N/A | E9: ='SCREENING - EXCLUDED'!E9 -> #N/A | F9: ='SCREENING - EXCLUDED'!F9 -> #N/A | G9: ='SCREENING - EXCLUDED'!G9 -> #N/A | H9: ='SCREENING - EXCLUDED'!H9 -> #N/A | ... M9: ='SCREENING - EXCLUDED'!M9 -> 0 | N9: X | P9: Yes
A10: ='SCREENING - EXCLUDED'!A10 -> #N/A | B10: ='SCREENING - EXCLUDED'!B10 -> #N/A | C10: ='SCREENING - EXCLUDED'!C10 -> #N/A | D10: ='SCREENING - EXCLUDED'!D10 -> #N/A | E10: ='SCREENING - EXCLUDED'!E10 -> #N/A | F10: ='SCREENING - EXCLUDED'!F10 -> #N/A | G10: ='SCREENING - EXCLUDED'!G10 -> #N/A | H10: ='SCREENING - EXCLUDED'!H10 -> #N/A | ... M10: ='SCREENING - EXCLUDED'!M10 -> 0 | N10: X | P10: Yes
A11: ='SCREENING - EXCLUDED'!A11 -> #N/A | B11: ='SCREENING - EXCLUDED'!B11 -> #N/A | C11: ='SCREENING - EXCLUDED'!C11 -> #N/A | D11: ='SCREENING - EXCLUDED'!D11 -> #N/A | E11: ='SCREENING - EXCLUDED'!E11 -> #N/A | F11: ='SCREENING - EXCLUDED'!F11 -> #N/A | G11: ='SCREENING - EXCLUDED'!G11 -> #N/A | H11: ='SCREENING - EXCLUDED'!H11 -> #N/A | ... M11: ='SCREENING - EXCLUDED'!M11 -> 0 | N11: X | P11: Yes
A12: ='SCREENING - EXCLUDED'!A12 -> #N/A | B12: ='SCREENING - EXCLUDED'!B12 -> #N/A | C12: ='SCREENING - EXCLUDED'!C12 -> #N/A | D12: ='SCREENING - EXCLUDED'!D12 -> #N/A | E12: ='SCREENING - EXCLUDED'!E12 -> #N/A | F12: ='SCREENING - EXCLUDED'!F12 -> #N/A | G12: ='SCREENING - EXCLUDED'!G12 -> #N/A | H12: ='SCREENING - EXCLUDED'!H12 -> #N/A | ... M12: ='SCREENING - EXCLUDED'!M12 -> 0 | N12: X | P12: Yes
A13: ='SCREENING - EXCLUDED'!A13 -> #N/A | B13: ='SCREENING - EXCLUDED'!B13 -> #N/A | C13: ='SCREENING - EXCLUDED'!C13 -> #N/A | D13: ='SCREENING - EXCLUDED'!D13 -> #N/A | E13: ='SCREENING - EXCLUDED'!E13 -> #N/A | F13: ='SCREENING - EXCLUDED'!F13 -> #N/A | G13: ='SCREENING - EXCLUDED'!G13 -> #N/A | H13: ='SCREENING - EXCLUDED'!H13 -> #N/A | ... M13: ='SCREENING - EXCLUDED'!M13 -> 0 | N13: X | P13: Yes
... A101: ='SCREENING - EXCLUDED'!A101 -> #N/A | B101: ='SCREENING - EXCLUDED'!B101 -> #N/A | C101: ='SCREENING - EXCLUDED'!C101 -> #N/A | D101: ='SCREENING - EXCLUDED'!D101 -> #N/A | E101: ='SCREENING - EXCLUDED'!E101 -> #N/A | F101: ='SCREENING - EXCLUDED'!F101 -> #N/A | G101: ='SCREENING - EXCLUDED'!G101 -> #N/A | H101: ='SCREENING - EXCLUDED'!H101 -> #N/A | ... M101: ='SCREENING - EXCLUDED'!M101 -> 0 | N101: X | P101: Yes
A102: ='SCREENING - EXCLUDED'!A102 -> #N/A | B102: ='SCREENING - EXCLUDED'!B102 -> #N/A | C102: ='SCREENING - EXCLUDED'!C102 -> #N/A | D102: ='SCREENING - EXCLUDED'!D102 -> #N/A | E102: ='SCREENING - EXCLUDED'!E102 -> #N/A | F102: ='SCREENING - EXCLUDED'!F102 -> #N/A | G102: ='SCREENING - EXCLUDED'!G102 -> #N/A | H102: ='SCREENING - EXCLUDED'!H102 -> #N/A | ... M102: ='SCREENING - EXCLUDED'!M102 -> 0 | O102: X | P102: Yes
A103: ='SCREENING - EXCLUDED'!A103 -> #N/A | B103: ='SCREENING - EXCLUDED'!B103 -> #N/A | C103: ='SCREENING - EXCLUDED'!C103 -> #N/A | D103: ='SCREENING - EXCLUDED'!D103 -> #N/A | E103: ='SCREENING - EXCLUDED'!E103 -> #N/A | F103: ='SCREENING - EXCLUDED'!F103 -> #N/A | G103: ='SCREENING - EXCLUDED'!G103 -> #N/A | H103: ='SCREENING - EXCLUDED'!H103 -> #N/A | ... M103: ='SCREENING - EXCLUDED'!M103 -> 0 | O103: X | P103: Yes
A104: ='SCREENING - EXCLUDED'!A104 -> #N/A | B104: ='SCREENING - EXCLUDED'!B104 -> #N/A | C104: ='SCREENING - EXCLUDED'!C104 -> #N/A | D104: ='SCREENING - EXCLUDED'!D104 -> #N/A | E104: ='SCREENING - EXCLUDED'!E104 -> #N/A | F104: ='SCREENING - EXCLUDED'!F104 -> #N/A | G104: ='SCREENING - EXCLUDED'!G104 -> #N/A | H104: ='SCREENING - EXCLUDED'!H104 -> #N/A | ... M104: ='SCREENING - EXCLUDED'!M104 -> 0 | O104: X | P104: Yes
A105: ='SCREENING - EXCLUDED'!A105 -> #N/A | B105: ='SCREENING - EXCLUDED'!B105 -> #N/A | C105: ='SCREENING - EXCLUDED'!C105 -> #N/A | D105: ='SCREENING - EXCLUDED'!D105 -> #N/A | E105: ='SCREENING - EXCLUDED'!E105 -> #N/A | F105: ='SCREENING - EXCLUDED'!F105 -> #N/A | G105: ='SCREENING - EXCLUDED'!G105 -> #N/A | H105: ='SCREENING - EXCLUDED'!H105 -> #N/A | ... M105: ='SCREENING - EXCLUDED'!M105 -> 0 | O105: X | P105: Yes
A106: ='SCREENING - EXCLUDED'!A106 -> #N/A | B106: ='SCREENING - EXCLUDED'!B106 -> #N/A | C106: ='SCREENING - EXCLUDED'!C106 -> #N/A | D106: ='SCREENING - EXCLUDED'!D106 -> #N/A | E106: ='SCREENING - EXCLUDED'!E106 -> #N/A | F106: ='SCREENING - EXCLUDED'!F106 -> #N/A | G106: ='SCREENING - EXCLUDED'!G106 -> #N/A | H106: ='SCREENING - EXCLUDED'!H106 -> #N/A | ... M106: ='SCREENING - EXCLUDED'!M106 -> 0 | O106: X | P106: Yes
